Performing system checks...

Starting email scheduler thread: <Thread(Thread-1 (schedule_email_sending), initial)>
Scheduling leave email
Scheduling reimbursement email
Scheduling reimbursement email (account)
Email scheduler started
System check identified no issues (0 silenced).
January 22, 2024 - 10:48:14
Django version 4.2, using settings 'hr_management.settings'
Starting development server at http://0.0.0.0:8080/
Quit the server with CONTROL-C.

send_leave_reminder_email
Leave email sent!
send_reimbursement_reminder_email
Reimbursement email sent!
send_reimbursement_reminder_email_account
Reimbursement email (account) sent!
Performing system checks...

Starting email scheduler thread: <Thread(Thread-1 (schedule_email_sending), initial)>
Scheduling leave email
Scheduling reimbursement email
Scheduling reimbursement email (account)
Email scheduler started
System check identified no issues (0 silenced).
January 23, 2024 - 21:12:52
Django version 4.2, using settings 'hr_management.settings'
Starting development server at http://0.0.0.0:8080/
Quit the server with CONTROL-C.

Performing system checks...

Starting email scheduler thread: <Thread(Thread-1 (schedule_email_sending), initial)>
Scheduling leave email
Scheduling reimbursement email
Scheduling reimbursement email (account)
Email scheduler started
System check identified no issues (0 silenced).
January 23, 2024 - 21:26:12
Django version 4.2, using settings 'hr_management.settings'
Starting development server at http://0.0.0.0:8080/
Quit the server with CONTROL-C.

Performing system checks...

Starting email scheduler thread: <Thread(Thread-1 (schedule_email_sending), initial)>
Scheduling leave email
Scheduling reimbursement email
Scheduling reimbursement email (account)
Email scheduler started
System check identified no issues (0 silenced).
January 23, 2024 - 21:26:14
Django version 4.2, using settings 'hr_management.settings'
Starting development server at http://0.0.0.0:8080/
Quit the server with CONTROL-C.

/home/hr/hrms/hrms_final/hr_management_app/AdminViews.py:1284: UnorderedObjectListWarning: Pagination may yield inconsistent results with an unordered object_list: <class 'hr_management_app.models.OfferLetter_Sended'> QuerySet.
  paginator = Paginator(offer_letters_sended, 10)  # 10 items per page
/home/hr/hrms/venv/lib/python3.10/site-packages/django/template/defaulttags.py:84: UserWarning: A {% csrf_token %} was used in a template, but the context did not provide the value.  This is usually caused by not using RequestContext.
  warnings.warn(
Traceback (most recent call last):
  File "/usr/lib/python3.10/wsgiref/handlers.py", line 138, in run
    self.finish_response()
  File "/home/hr/hrms/venv/lib/python3.10/site-packages/django/core/servers/basehttp.py", line 173, in finish_response
    super().finish_response()
  File "/usr/lib/python3.10/wsgiref/handlers.py", line 184, in finish_response
    self.write(data)
  File "/usr/lib/python3.10/wsgiref/handlers.py", line 293, in write
    self._write(data)
  File "/usr/lib/python3.10/wsgiref/handlers.py", line 467, in _write
    result = self.stdout.write(data)
  File "/usr/lib/python3.10/socketserver.py", line 826, in write
    self._sock.sendall(b)
TimeoutError: [Errno 110] Connection timed out
----------------------------------------
Exception occurred during processing of request from ('49.32.175.58', 54645)
Traceback (most recent call last):
  File "/usr/lib/python3.10/socketserver.py", line 683, in process_request_thread
    self.finish_request(request, client_address)
  File "/usr/lib/python3.10/socketserver.py", line 360, in finish_request
    self.RequestHandlerClass(request, client_address, self)
  File "/usr/lib/python3.10/socketserver.py", line 747, in __init__
    self.handle()
  File "/home/hr/hrms/venv/lib/python3.10/site-packages/django/core/servers/basehttp.py", line 229, in handle
    self.handle_one_request()
  File "/home/hr/hrms/venv/lib/python3.10/site-packages/django/core/servers/basehttp.py", line 237, in handle_one_request
    self.raw_requestline = self.rfile.readline(65537)
  File "/usr/lib/python3.10/socket.py", line 705, in readinto
    return self._sock.recv_into(b)
TimeoutError: [Errno 110] Connection timed out
----------------------------------------
